Workbook

Sheet TJ List
A1: Donations | B1: https://paypal.me/mlbplayeranalys?country.x=CA&locale.x=en_US
A2: Player | B2: TJ Surgery Date | C2: Team | D2: Level | E2: Position | F2: Throws | G2: Country | H2: High School | I2: College(s) | J2: Age | K2: Return Date (same level) | L2: Recovery Time (months) | M2: mlbamid | N2: fgid | O2: Surgeon(s) | P2: Post-TJ MLB G | Q2: Post-TJ MLB IP/PA | R2: Active | S2: Year | T2: Month | U2: Day | V2: Started Throwing | W2: Mound | X2: Bullpen | Y2: Live Hitters | Z2: Game | AA2: Setback | AB2: Setback Type | AC2: Setback | AD2: Setback Type | AE2: G | AF2: GS | AG2: IP | AH2: K-BB% | AI2: ERA- | AJ2: FIP- | AK2: G | AL2: GS | AM2: IP | AN2: K-BB% | AO2: ERA- | AP2: FIP-
A3: Ronny Henriquez | B3: 45992 | C3: MIA | D3: MLB | E3: P | F3: R | G3: Dominican | J3: 25 | M3: 678692 | N3: 24094 | O3: Dr. Keith Meister | P3: 0 | Q3: 0 | R3: 1 | S3: =YEAR(B3) -> 2025 | T3: =MONTH(B3) -> 12 | U3: =DAY(B3) -> 1
A4: Nic Enright | B4: 45959 | C4: CLE | D4: MLB | E4: P | F4: R | G4: United States | H4: Virginia | I4: Virginia Tech | J4: 28 | M4: 663671 | N4: 25553 | P4: 0 | Q4: 0 | R4: 1 | S4: =YEAR(B4) -> 2025 | T4: =MONTH(B4) -> 10 | U4: =DAY(B4) -> 29
A5: Reed Garrett | B5: 45938 | C5: NYM | D5: MLB | E5: P | F5: R | G5: United States | H5: Virginia | I5: Virginia Military | J5: 32 | M5: 657585 | N5: 16866 | P5: 0 | Q5: 0 | R5: 1 | S5: =YEAR(B5) -> 2025 | T5: =MONTH(B5) -> 10 | U5: =DAY(B5) -> 8
A6: Luis Garcia | B6: 45931 | C6: HOU | D6: MLB | E6: P | F6: R | G6: Venezuela | J6: 28 | M6: 677651 | N6: 23735 | P6: 0 | Q6: 0 | R6: 1 | S6: =YEAR(B6) -> 2025 | T6: =MONTH(B6) -> 10 | U6: =DAY(B6) -> 1
A7: Shelby Miller | B7: 45931 | C7: MIL | D7: MLB | E7: P | F7: R | G7: United States | H7: Texas | J7: 34 | M7: 571946 | N7: 10197 | O7: Dr. Keith Meister | P7: 0 | Q7: 0 | R7: 1 | S7: =YEAR(B7) -> 2025 | T7: =MONTH(B7) -> 10 | U7: =DAY(B7) -> 1
A8: Declan Cronin | B8: 45929 | C8: MIA | D8: AAA | E8: P | F8: R | G8: United States | H8: New York | I8: Holy Cross | J8: 27 | M8: 686539 | N8: 25645 | P8: 0 | Q8: 0 | R8: 1 | S8: =YEAR(B8) -> 2025 | T8: =MONTH(B8) -> 9 | U8: =DAY(B8) -> 29
A9: Randy Rodriguez | B9: 45924 | C9: SF | D9: MLB | E9: P | F9: R | G9: Dominican | J9: 25 | M9: 678495 | N9: 23974 | P9: 0 | Q9: 0 | R9: 1 | S9: =YEAR(B9) -> 2025 | T9: =MONTH(B9) -> 9 | U9: =DAY(B9) -> 24
A10: Brandon Walter | B10: 45922 | C10: HOU | D10: MLB | E10: P | F10: L | G10: United States | H10: Delaware | I10: Delaware | J10: 28 | M10: 687888 | N10: 26056 | P10: 0 | Q10: 0 | R10: 1 | S10: =YEAR(B10) -> 2025 | T10: =MONTH(B10) -> 9 | U10: =DAY(B10) -> 22
A11: Tylor Megill | B11: 45922 | C11: NYM | D11: AAA | E11: P | F11: R | G11: United States | H11: California | I11: Loyola Marymount, Arizona | J11: 29 | M11: 656731 | N11: 21318 | O11: Dr. Neal ElAttrache | P11: 0 | Q11: 0 | R11: 1 | S11: =YEAR(B11) -> 2025 | T11: =MONTH(B11) -> 9 | U11: =DAY(B11) -> 22
A12: Frankie Montas | B12: 45909 | C12: NYM | D12: MLB | E12: P | F12: R | G12: Dominican | J12: 32 | M12: 593423 | N12: 14309 | P12: 0 | Q12: 0 | R12: 1 | S12: =YEAR(B12) -> 2025 | T12: =MONTH(B12) -> 9 | U12: =DAY(B12) -> 9
A13: Tanner Houck | B13: 45875 | C13: BOS | D13: AAA | E13: P | F13: R | G13: United States | H13: Illinois | I13: Missouri | J13: 29 | M13: 656557 | N13: 19879 | O13: Dr. Keith Meister | P13: 0 | Q13: 0 | R13: 1 | S13: =YEAR(B13) -> 2025 | T13: =MONTH(B13) -> 8 | U13: =DAY(B13) -> 6
A14: Tyler Stuart | B14: 45870 | C14: WAS | D14: AA | E14: P | F14: R | G14: United States | H14: Illinois | I14: Southern Mississippi | J14: 25 | M14: 701603 | N14: sa3020264 | P14: 0 | Q14: 0 | R14: 1 | S14: =YEAR(B14) -> 2025 | T14: =MONTH(B14) -> 8 | U14: =DAY(B14) -> 1
A15: Travis Sykora | B15: 45870 | C15: WAS | D15: AA | E15: P | F15: R | G15: United States | H15: Texas | J15: 21 | M15: 805809 | N15: sa3023557 | P15: 0 | Q15: 0 | R15: 1 | S15: =YEAR(B15) -> 2025 | T15: =MONTH(B15) -> 8 | U15: =DAY(B15) -> 1
A16: Tekoah Roby | B16: 45863 | C16: STL | D16: AAA | E16: P | F16: R | G16: United States | H16: Florida | J16: 23 | M16: 694358 | N16: sa3014519 | P16: 0 | Q16: 0 | R16: 1 | S16: =YEAR(B16) -> 2025 | T16: =MONTH(B16) -> 7 | U16: =DAY(B16) -> 25
A17: Dedniel Nunez | B17: 45852 | C17: NYM | D17: MLB | E17: P | F17: R | G17: Dominican | J17: 29 | M17: 673380 | N17: 23055 | O17: Dr. Keith Meister | P17: 0 | Q17: 0 | R17: 1 | S17: =YEAR(B17) -> 2025 | T17: =MONTH(B17) -> 7 | U17: =DAY(B17) -> 14
A18: Zach Fogell | B18: 45839 | C18: BOS | D18: A+ | E18: P | F18: R | G18: United States | H18: Rhode Island | I18: Brown, Connecticut | J18: 24 | M18: 808820 | N18: sa3023280 | P18: 0 | Q18: 0 | R18: 1 | S18: =YEAR(B18) -> 2025 | T18: =MONTH(B18) -> 7 | U18: =DAY(B18) -> 1
A19: Peyton Prescott | B19: 45839 | C19: NYM | D19: Coll | E19: P | F19: R | G19: United States | H19: Florida | I19: Florida State, Jacksonville | J19: 21 | M19: 807290 | N19: sa3040183 | P19: 0 | Q19: 0 | R19: 1 | S19: =YEAR(B19) -> 2025 | T19: =MONTH(B19) -> 7 | U19: =DAY(B19) -> 1
A20: Trennor O'Donnell | B20: 45838 | C20: BOS | D20: A | E20: P | F20: R | G20: United States | H20: Texas | I20: Ball State | J20: 24 | M20: 815064 | N20: sa3023531 | P20: 0 | Q20: 0 | R20: 1 | S20: =YEAR(B20) -> 2025 | T20: =MONTH(B20) -> 6 | U20: =DAY(B20) -> 30
A21: Justin Martinez | B21: 45833 | C21: ARI | D21: MLB | E21: P | F21: R | G21: Dominican | J21: 23 | M21: 679885 | N21: 24453 | O21: Dr. Keith Meister | P21: 0 | Q21: 0 | R21: 1 | S21: =YEAR(B21) -> 2025 | T21: =MONTH(B21) -> 6 | U21: =DAY(B21) -> 25
A22: Jair Camargo | B22: 45833 | C22: MIN | D22: AAA | E22: C | F22: R | G22: Colombia | J22: 25 | M22: 665856 | N22: 21730 | O22: Dr. Christopher Camp | P22: 0 | Q22: 0 | R22: 1 | S22: =YEAR(B22) -> 2025 | T22: =MONTH(B22) -> 6 | U22: =DAY(B22) -> 25
A23: Jake Cousins | B23: 45826 | C23: NYY | D23: A+ | E23: P | F23: R | G23: United States | H23: Illinois | I23: Pennsylvania | J23: 30 | M23: 664776 | N23: 21620 | O23: Dr. Keith Meister | P23: 0 | Q23: 0 | R23: 1 | S23: =YEAR(B23) -> 2025 | T23: =MONTH(B23) -> 6 | U23: =DAY(B23) -> 18
A24: Jackson Jobe | B24: 45824 | C24: DET | D24: MLB | E24: P | F24: R | G24: United States | H24: Oklahoma | J24: 22 | M24: 695549 | N24: 30203 | O24: Dr. Keith Meister | P24: 0 | Q24: 0 | R24: 1 | S24: =YEAR(B24) -> 2025 | T24: =MONTH(B24) -> 6 | U24: =DAY(B24) -> 16
A25: Corbin Burnes | B25: 45819 | C25: ARI | D25: MLB | E25: P | F25: R | G25: United States | H25: California | I25: Saint Mary's | J25: 30 | M25: 669203 | N25: 19361 | O25: Dr. Neal ElAttrache | P25: 0 | Q25: 0 | R25: 1 | S25: =YEAR(B25) -> 2025 | T25: =MONTH(B25) -> 6 | U25: =DAY(B25) -> 11
A26: AJ Smith-Shawver | B26: 45817 | C26: ATL | D26: MLB | E26: P | F26: R | G26: United States | H26: Texas | J26: 22 | M26: 700363 | N26: 29960 | O26: Dr. Keith Meister | P26: 0 | Q26: 0 | R26: 1 | S26: =YEAR(B26) -> 2025 | T26: =MONTH(B26) -> 6 | U26: =DAY(B26) -> 9
A27: Will Brennan | B27: 45817 | C27: CLE | D27: MLB | E27: OF | F27: L | G27: United States | H27: Kansas | I27: Kansas State | J27: 27 | M27: 686823 | N27: 25660 | O27: Dr. Keith Meister | P27: 0 | Q27: 0 | R27: 1 | S27: =YEAR(B27) -> 2025 | T27: =MONTH(B27) -> 6 | U27: =DAY(B27) -> 9 | AA27: 45904 | AB27: Sports hernia surgery
A28: Ronel Blanco | B28: 45814 | C28: HOU | D28: MLB | E28: P | F28: R | G28: Dominican | J28: 31 | M28: 669854 | N28: 19407 | P28: 0 | Q28: 0 | R28: 1 | S28: =YEAR(B28) -> 2025 | T28: =MONTH(B28) -> 6 | U28: =DAY(B28) -> 6
A29: Ben Lively | B29: 45812 | C29: CLE | D29: MLB | E29: P | F29: R | G29: United States | H29: Florida | I29: Central Florida | J29: 33 | M29: 594902 | N29: 14932 | O29: Dr. Keith Meister | P29: 0 | Q29: 0 | R29: 1 | S29: =YEAR(B29) -> 2025 | T29: =MONTH(B29) -> 6 | U29: =DAY(B29) -> 4
A30: Evan Phillips | B30: 45812 | C30: LAD | D30: MLB | E30: P | F30: R | G30: United States | H30: North Carolina | I30: North Carolina | J30: 30 | M30: 623465 | N30: 17734 | O30: Dr. Neal ElAttrache | P30: 0 | Q30: 0 | R30: 1 | S30: =YEAR(B30) -> 2025 | T30: =MONTH(B30) -> 6 | U30: =DAY(B30) -> 4
A31: Tommy Henry | B31: 45809 | C31: ARI | D31: MLB | E31: P | F31: L | G31: United States | H31: Michigan | I31: Michigan | J31: 27 | M31: 674072 | N31: 26285 | P31: 0 | Q31: 0 | R31: 1 | S31: =YEAR(B31) -> 2025 | T31: =MONTH(B31) -> 6 | U31: =DAY(B31) -> 1
A32: Yordanny Monegro | B32: 45809 | C32: BOS | D32: AA | E32: P | F32: R | G32: Dominican | J32: 22 | M32: 694057 | N32: sa3015476 | P32: 0 | Q32: 0 | R32: 1 | S32: =YEAR(B32) -> 2025 | T32: =MONTH(B32) -> 6 | U32: =DAY(B32) -> 1
A33: Emmett Olson | B33: 45809 | C33: MIA | D33: A+ | E33: P | F33: L | G33: United States | H33: Illinois | I33: Nebraska | J33: 23 | M33: 801207 | N33: sa3023223 | P33: 0 | Q33: 0 | R33: 1 | S33: =YEAR(B33) -> 2025 | T33: =MONTH(B33) -> 6 | U33: =DAY(B33) -> 1
A34: Hayden Wesneski | B34: 45800 | C34: HOU | D34: MLB | E34: P | F34: R | G34: United States | H34: Texas | I34: Sam Houston State | J34: 27 | M34: 669713 | N34: 27581 | P34: 0 | Q34: 0 | R34: 1 | S34: =YEAR(B34) -> 2025 | T34: =MONTH(B34) -> 5 | U34: =DAY(B34) -> 23
A35: Patrick Reilly | B35: 45791 | C35: BAL | D35: AA | E35: P | F35: R | G35: United States | H35: New Jersey | I35: Vanderbilt | J35: 23 | M35: 694345 | N35: sa3023038 | O35: Dr. Keith Meister | P35: 0 | Q35: 0 | R35: 1 | S35: =YEAR(B35) -> 2025 | T35: =MONTH(B35) -> 5 | U35: =DAY(B35) -> 14
A36: Casey Saucke | B36: 45778 | C36: CHW | D36: A | E36: OF | F36: R | G36: United States | H36: New York | I36: Virginia | J36: 21 | M36: 695565 | N36: sa3025382 | P36: 0 | Q36: 0 | R36: 1 | S36: =YEAR(B36) -> 2025 | T36: =MONTH(B36) -> 5 | U36: =DAY(B36) -> 1
A37: Danny Young | B37: 45778 | C37: NYM | D37: MLB | E37: P | F37: L | G37: United States | H37: Florida | I37: Florida | J37: 31 | M37: 664849 | N37: 18439 | P37: 0 | Q37: 0 | R37: 1 | S37: =YEAR(B37) -> 2025 | T37: =MONTH(B37) -> 5 | U37: =DAY(B37) -> 1
A38: Edgar Barclay | B38: 45778 | C38: NYY | D38: AA | E38: P | F38: L | G38: United States | H38: Oklahoma | I38: Cal State Bakersfield | J38: 27 | M38: 687607 | N38: sa1170012 | P38: 0 | Q38: 0 | R38: 1 | S38: =YEAR(B38) -> 2025 | T38: =MONTH(B38) -> 5 | U38: =DAY(B38) -> 1
A39: Moises Chace | B39: 45778 | C39: PHI | D39: AA | E39: P | F39: R | G39: Venezuela | J39: 22 | M39: 691330 | N39: sa3015346 | P39: 0 | Q39: 0 | R39: 1 | S39: =YEAR(B39) -> 2025 | T39: =MONTH(B39) -> 5 | U39: =DAY(B39) -> 1
A40: Sem Robberse | B40: 45778 | C40: STL | D40: AAA | E40: P | F40: R | G40: Netherlands | J40: 23 | M40: 691828 | N40: sa3011735 | P40: 0 | Q40: 0 | R40: 1 | S40: =YEAR(B40) -> 2025 | T40: =MONTH(B40) -> 5 | U40: =DAY(B40) -> 1
...

Sheet How To Use
A1: Important usage notes:
A2: - Creating and maintaining this database has required thousands of hours of work since 2012. I am committed to keeping it publically available for free.
A3: - If you have benefitted from using the database and wish to make a donation, you may do so at https://paypal.me/mlbplayeranalys?country.x=CA&locale.x=en_US
A4: - This list is *not* a complete list of *all* Tommy John surgeries. The list contains entries for all Tommy John surgeries of MLB and MiLB players that have been confirmed through media reports of some kind.
A5: - Some teams are much more guarded in releasing information about Tommy John surgeries than other teams. Some teams have beat writers or prospect writers who dig for MiLB injury statuses more than other teams.
A6: - Some Tommy John surgeries go completely unreported by the media and will not appear in this list.
A7: - Additional player information comes from Baseball Reference, Fangraphs, Baseball Cube, MiLB.com.
A8: - When the month of the surgery is known but not the exact date, MM/1/YYYY is used for the surgery date.
A9: - When the year of the surgery is known but not the month or date, 1/1/YYYY is used for the surgery date.
A10: - 'Level' is the level of baseball in which the player played his last game prior to having Tommy John surgery. Some players listed with an MiLB level have had previous MLB experience.
A11: - After the MLB Draft in June, players who sign who have had Tommy John surgery are added to the TJ List. Unsigned drafted players remain in the Unsigned Draftees list.
A12: - UCL PRP tracks players who had PRP/stem cell injections specifically due to UCL damage (i.e. not flexor tendon).
... A14: - UCL InternalBrace was developed by Dr. Jeffrey Dugas at ASMI.

Sheet Pending
A1: Player | B1: Notes
A2: Vinny Nittoli | B2: SEA, MiLB, RHP, one reference had it in 2014, can't confirm
A3: Bryan Blanton | B3: NYY, MiLB, RHP, unconfirmed that he had TJ surgery | C3: https://twitter.com/jeremyarroyo/status/1371651765528113153?s=11
A4: Rodney Theophile | B4: WAS, MiLB, RHP, unconfirmed that he had TJ surgery | C4: https://twitter.com/nicabeis/status/1389778623608012801?s=11
A5: Dane Acker | B5: TEX, MiLB, RHP, elbow surgery 5/26, either TJ or InternalBrace
A6: Angel Benitez | B6: NYY, MiLB, had TJ surgery but was it 2022 or early 2023 | C6: https://twitter.com/NYY_Prospects/status/1617992159097151489
A7: Hunter Bishop | B7: SF, MiLB, A+, OF, had UCL surgery 4/1, not sure which kind
A8: Brandon White | B8: PIT, MiLB, need to confirm had TJ
A9: Yoelvis Sanchez | B9: PIT, MiLB, need to confirm had TJ
A10: Julio Mendez | B10: PIT, MiLB, need to confirm had TJ
A11: Hayden Robinson | B11: MIL, MiLB, needs surgery, either TJ or internal brace
A12: Alejandro Rosario | B12: TEX, MiLB, needs second TJ surgery? | C12: https://x.com/picksshelf/status/1893419808869294186?s=43&t=NO0hlvLBbI0JRudVD13oLg
A13: Alex Young | B13: CIN, LHP, may need TJ surgery
A14: Jake Bloss | B14: TOR, MiLB, RHP, having some form of UCL surgery with Dr. Meister
A15: Nick Judice | B15: BOS, had some arm surgery, maybe TJ | C15: https://x.com/ByAndrewParker/status/1946640944582864933
A16: Carson Spiers | B16: CIN, MLB. had UCL surgery with Dr. Meister, either TJ or IB
A17: Manuel Rodriguez | B17: TB, MLB, had surgery 8/8, were going to look at UCL, Dr. Meister

Sheet UCL PRP
A1: Player | B1: PRP Injection Date | C1: Stem Cell? | D1: Team | E1: Level | F1: Return Date (same level) | G1: Recovery Time (months) | H1: TJ Surgery Date | I1: UCL Damage Description
A2: Graham Ashcraft | B2: 45483 | D2: CIN | E2: MLB
A3: Jeff McNeil | B3: 45200 | D3: NYM | E3: MLB
A4: Ryan Weber | B4: 45078 | D4: NYY | E4: MLB
A5: Bryce Harper | B5: 44696 | D5: PHI | E5: MLB | H5: 44888
A6: Chris Paddack | B6: 44466 | D6: SD | E6: MLB | F6: 44664 | G6: =ROUND(((F6-B6)/365)*12,0) -> 7 | H6: 44699
A7: Nick Burdi | B7: 44044 | D7: PIT | E7: MLB | H7: 44118
A8: Griffin Canning | B8: 43896 | D8: LAA | E8: MLB | F8: 44294 | G8: =ROUND(((F8-B8)/365)*12,0) -> 13
A9: John Brebbia | B9: 43891 | D9: STL | E9: MLB | H9: 43990
A10: Kent Emanuel | B10: 43831 | D10: HOU | E10: AAA | F10: 44310
A11: Tommy Pham | B11: 43831 | C11: Y | D11: TB | E11: MLB | F11: 44287
A12: Steven Wright | B12: 43678 | D12: BOS | E12: MLB | H12: 43760
A13: Blaine Hardy | B13: 43678 | D13: DET | E13: MLB | H13: 43910
A14: Seranthony Dominguez | B14: 43630 | D14: PHI | E14: MLB | H14: 44042
A15: T.J. Rivera | B15: 43297 | D15: NYM | E15: MLB
A16: Shohei Ohtani | B16: 43258 | C16: Y | D16: LAA | E16: MLB | F16: 43345 | G16: =ROUND(((F16-B16)/365)*12,0) -> 3 | H16: 43374 | I16: 2nd-grade tear (unrelated to previous tear)
A17: Shohei Ohtani | B17: 43009 | D17: LAA | E17: MLB | F17: 43188 | G17: =ROUND(((F17-B17)/365)*12,0) -> 6 | H17: 43374 | I17: 1st-degree tear
A18: Matt Givin | B18: 43009 | D18: MIA | E18: Rk | H18: 43207
A19: Wei-Yin Chen | B19: 43005 | D19: MIA | E19: MLB | F19: 43218 | G19: =ROUND(((F19-B19)/365)*12,0) -> 7
A20: JC Ramirez | B20: 42971 | C20: Y | D20: LAA | E20: MLB | F20: 43192 | G20: =ROUND(((F20-B20)/365)*12,0) -> 7 | H20: 43207 | I20: partial tear
A21: T.J. Rivera | B21: 42944 | D21: NYM | E21: MLB | H21: 42992
A22: Anthony Santander | B22: 42864 | D22: BAL | E22: A+ | F22: 42943 | G22: =ROUND(((F22-B22)/365)*12,0) -> 3
A23: Branden Kline | B23: 42840 | D23: BAL | E23: AA | F23: 43240 | G23: =ROUND(((F23-B23)/365)*12,0) -> 13
A24: Seth Lugo | B24: 42829 | D24: NYM | E24: MLB | F24: 42897 | G24: =ROUND(((F24-B24)/365)*12,0) -> 2 | I24: slight tear
A25: Chi Chi Gonzalez | B25: 42815 | D25: TEX | E25: AAA | H25: 42917 | I25: partial tear (10%)
A26: Victor Arano | B26: 42788 | D26: PHI | E26: AA | F26: 42886 | G26: =ROUND(((F26-B26)/365)*12,0) -> 3
A27: Keston Hiura | B27: 42736 | D27: MIL | E27: Coll | F27: 42784 | G27: =ROUND(((F27-B27)/365)*12,0) -> 2
A28: Yimmi Brasoban | B28: 42675 | C28: Y | D28: SD | E28: AA | F28: 42899 | G28: =ROUND(((F28-B28)/365)*12,0) -> 7
A29: Rubby De La Rosa | B29: 42640 | C29: Y | D29: ARI | E29: MLB | F29: 42909 | G29: =ROUND(((F29-B29)/365)*12,0) -> 9 | H29: 42969 | I29: stretch (tried PRP earlier in summer too)
A30: Colin Rea | B30: 42600 | D30: SD | E30: MLB | H30: 42684 | I30: partial tear
A31: Aaron Nola | B31: 42599 | D31: PHI | E31: MLB | F31: 42833 | G31: =ROUND(((F31-B31)/365)*12,0) -> 8 | I31: low-grade tear
A32: Wei-Yin Chen | B32: 42583 | D32: MIA | E32: MLB | F32: 42632 | G32: =ROUND(((F32-B32)/365)*12,0) -> 2 | I32: slight tear
A33: Jon Edwards | B33: 42522 | D33: SD | E33: MLB | F33: 43344 | G33: =ROUND(((F33-B33)/365)*12,0) -> 27 | I33: wear
A34: Garrett Richards | B34: 42506 | C34: Y | D34: LAA | E34: MLB | F34: 42830 | G34: =ROUND(((F34-B34)/365)*12,0) -> 11 | H34: 43305 | I34: lengthwise tear down middle (20-25%)
A35: Sean Nolin | B35: 42491 | D35: MIL | E35: MLB | H35: 42583 | I35: partial tear
A36: Andrew Heaney | B36: 42491 | C36: Y | D36: LAA | E36: MLB | H36: 42552 | I36: some degree of tear
A37: Michael Lorenzen | B37: 42461 | D37: CIN | E37: MLB | F37: 42545 | G37: =ROUND(((F37-B37)/365)*12,0) -> 3 | I37: mild tear
A38: Connor Strain | B38: 42370 | D38: LAD | E38: Coll | F38: 42783
A39: Casey Sadler | B39: 42211 | D39: PIT | E39: AAA | H39: 42278 | I39: unknown
A40: Alex Cobb | B40: 42130 | D40: TB | E40: MLB | H40: 42138 | I40: partial tear
...

Sheet UCL InternalBrace
A1: Player | B1: UCL primary repair with internal brace construction Date | C1: Team | D1: Level | E1: Return Date (same level) | F1: Recovery Time (months) | G1: Return Date (any level) | H1: TJ Surgery Date | I1: Surgeon(s) | J1: Recovery Schedule
A2: Humberto Cruz | B2: 45870 | C2: SD | D2: A
A3: Trevor Williams | B3: 45855 | C3: WAS | D3: MLB | I3: Dr. Jeffrey Dugas
A4: Connor Thomas | B4: 45854 | C4: MIL | D4: Rk
A5: Clarke Schmidt | B5: 45849 | C5: NYY | D5: MLB | I5: Dr. Keith Meister
A6: Cody Bradford | B6: 45833 | C6: TEX | D6: MLB | I6: Dr. Keith Meister
A7: A.J. Puk | B7: 45828 | C7: ARI | D7: MLB | I7: Dr. Neal ElAttrache
A8: Jared Jones | B8: 45798 | C8: PIT | D8: MLB | I8: Dr. Keith Meister
A9: Ben Abeldt | B9: 45689 | C9: TEX | D9: Coll | I9: Dr. Keith Meister
A10: Trei Cruz | B10: 45505 | C10: DET | D10: AA
A11: Patrick Sandoval | B11: 45469 | C11: LAA | D11: MLB
A12: Tyler Wells | B12: 45460 | C12: BAL | D12: MLB | E12: 45902 | F12: =ROUND(((E12-B12)/365)*12,0) -> 15 | I12: Dr. Keith Meister
A13: Garrett Whitlock | B13: 45442 | C13: BOS | D13: MLB | E13: 45743 | F13: =ROUND(((E13-B13)/365)*12,0) -> 10 | G13: 45743 | I13: Dr. Jeffrey Dugas
A14: Nate Lavender | B14: 45413 | C14: NYM | D14: AAA
A15: Landen Maroudis | B15: 45413 | C15: TOR | D15: A | G15: 45780
A16: Spencer Strider | B16: 45394 | C16: ATL | D16: MLB | E16: 45762 | F16: =ROUND(((E16-B16)/365)*12,0) -> 12 | G16: 45745 | I16: Dr. Keith Meister
A17: Jonathan Loaisiga | B17: 45394 | C17: NYY | D17: MLB | E17: 45793 | F17: =ROUND(((E17-B17)/365)*12,0) -> 13 | G17: 45773 | I17: Dr. Keith Meister
A18: Tejay Antone | B18: 45383 | C18: CIN | D18: MLB | I18: Dr. Timonthy Kremchek
A19: Lucas Giolito | B19: 45363 | C19: BOS | D19: MLB | E19: 45777 | F19: =ROUND(((E19-B19)/365)*12,0) -> 14 | G19: 45749 | I19: Dr. Jeffrey Dugas
A20: Brendan Donovan | B20: 45140 | C20: STL | D20: MLB | E20: 45379 | F20: =ROUND(((E20-B20)/365)*12,0) -> 8 | G20: 45379 | I20: Dr. Keith Meister
A21: Drew Rasmussen | B21: 45131 | C21: TB | D21: MLB | E21: 45511 | F21: =ROUND(((E21-B21)/365)*12,0) -> 12 | I21: Dr. Keith Meister
A22: Connor Prielipp | B22: 45124 | C22: MIN | D22: Rk | I22: Dr. Keith Meister
A23: Vince Velasquez | B23: 45086 | C23: PIT | D23: MLB | I23: Dr. Neal ElAttrache
A24: Trevor Story | B24: 44935 | C24: BOS | D24: MLB | E24: 45146 | F24: =ROUND(((E24-B24)/365)*12,0) -> 7 | G24: 45128 | I24: Dr. Keith Meister
A25: Eduardo Valencia | B25: 44927 | C25: DET | D25: A+ | G25: 45389
A26: Talon Haley | B26: 44927 | C26: LAA | D26: HS
A27: Isaac Ayon | B27: 44866 | C27: LAD | D27: Coll | H27: 45292
A28: Aaron Zavala | B28: 44866 | C28: TEX | D28: AA | E28: 45063 | F28: =ROUND(((E28-B28)/365)*12,0) -> 6 | G28: 45063
A29: Sean Doolittle | B29: 44743 | C29: WAS | D29: MLB | G29: 45073
A30: Adam Meier | B30: 44652 | C30: ATL | D30: Coll
A31: Will Kincanon | B31: 44628 | C31: CHW | D31: AA | G31: 45063 | I31: Dr. Lyle Cain
A32: Nick Conte | B32: 44562 | C32: KC | D32: Coll | G32: 45356
A33: Nick Anderson | B33: 44470 | C33: TB | D33: MLB | E33: 45017 | F33: =ROUND(((E33-B33)/365)*12,0) -> 18 | G33: 44764
A34: Zach Britton | B34: 44447 | C34: NYY | D34: MLB | E34: 44828 | F34: =ROUND(((E34-B34)/365)*12,0) -> 13 | G34: 44797 | I34: Dr. Neal ElAttrache
A35: Eli White | B35: 44447 | C35: TEX | D35: MLB | E35: 44660 | F35: =ROUND(((E35-B35)/365)*12,0) -> 7 | G35: 44695 | I35: Dr. Keith Meister
A36: Garrett Cooper | B36: 44409 | C36: MIA | D36: MLB | E36: 44659 | F36: =ROUND(((E36-B36)/365)*12,0) -> 8 | G36: 44659
A37: Tyree Thompson | B37: 44375 | C37: TEX | D37: A | E37: 44675 | F37: =ROUND(((E37-B37)/365)*12,0) -> 10 | G37: 44675 | I37: Dr. Keith Meister
A38: Kent Emanuel | B38: 44350 | C38: HOU | D38: MLB | G38: 44721 | I38: Dr. Jeffrey Dugas
A39: Bryan Woo | B39: 44287 | C39: SEA | D39: Coll | E39: 44718 | F39: =ROUND(((E39-B39)/365)*12,0) -> 14 | G39: 44718
A40: Lazaro Estrada | B40: 44197 | C40: TOR | D40: A | E40: 44778 | G40: 44757
...

Sheet Repeat TJ List
A1: Player | B1: TJ Surgery Date | C1: Back to Playing? | D1: Years Between | E1: Surgeon | F1: 2nd Surgeon | G1: Same? | H1: Multiple TJ | I1: Count
A2: Adam Choplick | B2: 40544 | C2: Back | D2: =MAX((B2-B3)/365, 1) -> 1 | H2: Same Surgeon | I2: =COUNTIF(G:G,1) -> 30
A3: Adam Choplick | B3: 40280 | E3: Unknown | H3: Diff Suregon | I3: =COUNTIF(G:G,0) -> 28
A4: Adam Parks | B4: 42544 | C4: Back | D4: =MAX((B4-B5)/365, 1) -> 4.4794521
A5: Adam Parks | B5: 40909 | E5: Unknown
A6: Al Reyes | B6: 38643 | C6: Back | D6: =MAX((B6-B7)/365, 1) -> 10.221918
A7: Al Reyes | B7: 34912 | E7: Unknown
A8: Alfredo Silverio | B8: 41451 | C8: Back | D8: =MAX((B8-B9)/365, 1) -> 1.1315068
A9: Alfredo Silverio | B9: 41038 | E9: Unknown
A10: Anderson Espinoza | B10: 43577 | C10: Back | D10: =MAX((B10-B11)/365, 1) -> 1.7260274 | F10: Dr. Keith Meister | G10: 1
A11: Anderson Espinoza | B11: 42947 | E11: Dr. Keith Meister
A12: Andrew Lee | B12: 42580 | C12: Back | D12: =MAX((B12-B13)/365, 1) -> 4.5780822
A13: Andrew Lee | B13: 40909 | E13: Unknown
A14: Andrew McKirahan | B14: 42439 | C14: Not back | D14: =MAX((B14-B15)/365, 1) -> 3.660274 | F14: Dr. James Andrews | G14: 0
A15: Andrew McKirahan | B15: 41103 | E15: Dr. Stephen Gryzlo
A16: Artie Lewicki | B16: 43313 | C16: Back | D16: =MAX((B16-B17)/365, 1) -> 6.0027397
A17: Artie Lewicki | B17: 41122 | E17: Dr. Christopher Ahmad
A18: Ben Leeper | B18: 45017 | C18: Not yet | D18: =MAX((B18-B19)/365, 1) -> 7.2520548
A19: Ben Leeper | B19: 42370 | C19: Back | D19: =MAX((B19-B20)/365, 1) -> 1.5041096 | E19: Unknown
A20: Ben Leeper | B20: 41821 | E20: Unknown
A21: Blaine Howell | B21: 41275 | C21: Back | D21: =MAX((B21-B22)/365, 1) -> 1.0027397
A22: Blaine Howell | B22: 40909 | E22: Unknown
A23: Blake Wood | B23: 43250 | C23: Not back | D23: =MAX((B23-B24)/365, 1) -> 6.0164384 | F23: Dr. Neal ElAttrache | G23: 0
A24: Blake Wood | B24: 41054 | E24: {=INDEX('TJ List'!O:O,MATCH(A24&B24,'TJ List'!A:A&'TJ List'!B:B,0))} -> Dr. Lewis Yocum
A25: Blayne Enlow | B25: 45383 | C25: Not yet | D25: =MAX((B25-B26)/365, 1) -> 2.8136986
A26: Blayne Enlow | B26: 44356 | E26: Unknown
A27: Brad Wieck | B27: 44762 | C27: Not yet | D27: =MAX((B27-B28)/365, 1) -> 11.394521
A28: Brad Wieck | B28: 40603 | E28: Unknown
A29: Brandon Bailey | B29: 44228 | C29: Not back | D29: =MAX((B29-B30)/365, 1) -> 8.5342466
A30: Brandon Bailey | B30: 41113 | E30: Unknown
A31: Brandon Beachy | B31: 41719 | C31: Back | D31: =MAX((B31-B32)/365, 1) -> 1.7479452 | F31: Dr. Neal ElAttrache | G31: 0
A32: Brandon Beachy | B32: 41081 | E32: {=INDEX('TJ List'!O:O,MATCH(A32&B32,'TJ List'!A:A&'TJ List'!B:B,0))} -> Dr. James Andrews
A33: Brandon Young | B33: 44562 | C33: Back | D33: =MAX((B33-B34)/365, 1) -> 8.0054795
A34: Brandon Young | B34: 41640 | E34: Unknown
A35: Braxton Garrett | B35: 45640 | C35: Not yet | D35: =MAX((B35-B36)/365, 1) -> 7.490411
A36: Braxton Garrett | B36: 42906 | E36: {=INDEX('TJ List'!O:O,MATCH(A36&B36,'TJ List'!A:A&'TJ List'!B:B,0))} -> Dr. James Andrews
A37: Brian Anderson | B37: 38718 | C37: Not back | D37: =MAX((B37-B38)/365, 1) -> 1 | F37: Dr. Timothy Kremchek | G37: 1
A38: Brian Anderson | B38: 38554 | E38: {=INDEX('TJ List'!O:O,MATCH(A38&B38,'TJ List'!A:A&'TJ List'!B:B,0))} -> Dr. Timothy Kremchek
A39: Brian Wilson | B39: 41018 | C39: Back | D39: =MAX((B39-B40)/365, 1) -> 9.3041096
A40: Brian Wilson | B40: 37622 | E40: Unknown
...

Sheet MLB 2024
A1: 2024 MLB Pitchers Who Have Had TJ Surgery, By Team & Usage | G1: Pitcher Used in 2024 | H1: Team | I1: playerid | J1: TJ | L1: Pitcher on IL | M1: Team | N1: City | O1: playerid | P1: TJ | Q1: Already | S1: Position Player | T1: Team | U1: playerid | W1: Pitcher Used in 2024 | X1: Team | Y1: playerid | Z1: TJ
A2: Team | B2: Pitchers Used | C2: Pitchers | D2: Pitchers Not Used, on IL | E2: Pitchers on IL | G2: Yusei Kikuchi | H2: - - - | I2: 20633 | J2: {=INDEX('TJ List'!B:B,MATCH(I2,'TJ List'!N:N,0),0)} -> #N/A | L2: Drey Jameson | M2: ARI | N2: Arizona | O2: 26260 | P2: {=INDEX('TJ List'!B:B,MATCH(O2,'TJ List'!N:N,0),0)} -> 45170 | Q2: {=IFERROR(INDEX(I:I,MATCH(O2,I:I,0),0),0)} -> 0 | S2: Eddy Alvarez | T2: NYM | U2: 16959 | W2: Andrew Chafin | X2: - - - | Y2: 12988 | Z2: 39973
A3: LAD | B3: =COUNTIFS(H:H,A3,J:J,">0") -> 18 | C3: =IFERROR(__xludf.DUMMYFUNCTION("IF(B3>0,JOIN("", "",TRANSPOSE(INDIRECT(ADDRESS(MATCH(A3,H:H,0),7)&"":""&ADDRESS(MATCH(A3,H:H,0)+B3-1,7)))),"""")"),"Daniel Hudson, Ryan Brasier, Brusdar Graterol, Michael Grove, Brent Honeywell, Dinelson Lamet, Anthony Banda, Michael Kopech, Gus Varland, Ricky Vanasco, James Paxton, Justin Wrobleski, Tyler Glasnow, Edgardo Henriquez, Walker Buehler, Kyle Hurt, River Ry"&"an, Yoshinobu Yamamoto") -> Daniel Hudson, Ryan Brasier, Brusdar Graterol, Michael Grove, Brent Honeywell, Dinelson Lamet, Anthony Banda, Michael Kopech, Gus Varland, Ricky Vanasco, James Paxton, Justin Wrobleski, Tyler Glasnow, Edgardo Henriquez, Walker Buehler, Kyle Hurt, River Ryan, Yoshinobu Yamamoto | D3: =COUNTIFS(M:M,A3,P:P,">0",Q:Q,0) -> 3 | E3: =IFERROR(__xludf.DUMMYFUNCTION("IF(D3>0,JOIN("", "",TRANSPOSE(INDIRECT(ADDRESS(MATCH(A3,M:M,0),12)&"":""&ADDRESS(MATCH(A3,M:M,0)+D3-1,12)))),"""")"),"Dustin May, Tony Gonsolin, Emmet Sheehan") -> Dustin May, Tony Gonsolin, Emmet Sheehan | G3: Jack Flaherty | H3: - - - | I3: 17479 | J3: {=INDEX('TJ List'!B:B,MATCH(I3,'TJ List'!N:N,0),0)} -> #N/A | L3: Huascar Ynoa | M3: ATL | N3: Atlanta | O3: 20468 | P3: {=INDEX('TJ List'!B:B,MATCH(O3,'TJ List'!N:N,0),0)} -> 44811 | Q3: {=IFERROR(INDEX(I:I,MATCH(O3,I:I,0),0),0)} -> 0 | S3: Tucker Barnhart | T3: ARI | U3: 10200 | W3: JT Chargois | X3: - - - | Y3: 13767 | Z3: 41534
A4: NYY | B4: =COUNTIFS(H:H,A4,J:J,">0") -> 18 | C4: =IFERROR(__xludf.DUMMYFUNCTION("IF(B4>0,JOIN("", "",TRANSPOSE(INDIRECT(ADDRESS(MATCH(A4,H:H,0),7)&"":""&ADDRESS(MATCH(A4,H:H,0)+B4-1,7)))),"""")"),"Ron Marinaccio, Clay Holmes, Jonathan Loáisiga, Victor González, Clarke Schmidt, Clayton Beeter, Mark Leiter Jr., Carlos Rodón, Tim Mayza, Tommy Kahnle, Caleb Ferguson, Nick Burdi, Yoendrys Gómez, Luis Gil, Cody Poteet, Scott Effross, Nestor Cortes, Gerri"&"t Cole") -> Ron Marinaccio, Clay Holmes, Jonathan Loáisiga, Victor González, Clarke Schmidt, Clayton Beeter, Mark Leiter Jr., Carlos Rodón, Tim Mayza, Tommy Kahnle, Caleb Ferguson, Nick Burdi, Yoendrys Gómez, Luis Gil, Cody Poteet, Scott Effross, Nestor Cortes, Gerrit Cole | D4: =COUNTIFS(M:M,A4,P:P,">0",Q:Q,0) -> 2 | E4: =IFERROR(__xludf.DUMMYFUNCTION("IF(D4>0,JOIN("", "",TRANSPOSE(INDIRECT(ADDRESS(MATCH(A4,M:M,0),12)&"":""&ADDRESS(MATCH(A4,M:M,0)+D4-1,12)))),"""")"),"JT Brubaker, Lou Trivino") -> JT Brubaker, Lou Trivino | G4: Zach Eflin | H4: - - - | I4: 13774 | J4: {=INDEX('TJ List'!B:B,MATCH(I4,'TJ List'!N:N,0),0)} -> #N/A | L4: Angel Perdomo | M4: ATL | N4: Atlanta | O4: 17759 | P4: {=INDEX('TJ List'!B:B,MATCH(O4,'TJ List'!N:N,0),0)} -> 45205 | Q4: {=IFERROR(INDEX(I:I,MATCH(O4,I:I,0),0),0)} -> 0 | S4: Jake Bauers | T4: MIL | U4: 15194 | W4: Mitch White | X4: - - - | Y4: 19225 | Z4: 41579
A5: COL | B5: =COUNTIFS(H:H,A5,J:J,">0") -> 16 | C5: =IFERROR(__xludf.DUMMYFUNCTION("IF(B5>0,JOIN("", "",TRANSPOSE(INDIRECT(ADDRESS(MATCH(A5,H:H,0),7)&"":""&ADDRESS(MATCH(A5,H:H,0)+B5-1,7)))),"""")"),"Cal Quantrill, Noah Davis, Seth Halvorsen, Josh Rogers, Matt Carasiti, Ty Blach, Peter Lambert, Jalen Beeks, Dakota Hudson, Jaden Hill, John Curtiss, Bradley Blalock, Lucas Gilbreath, Germán Márquez, Antonio Senzatela, Ryan Feltner") -> Cal Quantrill, Noah Davis, Seth Halvorsen, Josh Rogers, Matt Carasiti, Ty Blach, Peter Lambert, Jalen Beeks, Dakota Hudson, Jaden Hill, John Curtiss, Bradley Blalock, Lucas Gilbreath, Germán Márquez, Antonio Senzatela, Ryan Feltner | D5: =COUNTIFS(M:M,A5,P:P,">0",Q:Q,0) -> 0 | E5: =IFERROR(__xludf.DUMMYFUNCTION("IF(D5>0,JOIN("", "",TRANSPOSE(INDIRECT(ADDRESS(MATCH(A5,M:M,0),12)&"":""&ADDRESS(MATCH(A5,M:M,0)+D5-1,12)))),"""")"),"") | G5: Lucas Erceg | H5: - - - | I5: 19360 | J5: {=INDEX('TJ List'!B:B,MATCH(I5,'TJ List'!N:N,0),0)} -> #N/A | L5: Félix Bautista | M5: BAL | N5: Baltimore | O5: 20666 | P5: {=INDEX('TJ List'!B:B,MATCH(O5,'TJ List'!N:N,0),0)} -> 45208 | Q5: {=IFERROR(INDEX(I:I,MATCH(O5,I:I,0),0),0)} -> 0 | S5: David Bote | T5: CHC | U5: 14593 | W5: Cole Irvin | X5: - - - | Y5: 19244 | Z5: 41673
A6: DET | B6: =COUNTIFS(H:H,A6,J:J,">0") -> 16 | C6: =IFERROR(__xludf.DUMMYFUNCTION("IF(B6>0,JOIN("", "",TRANSPOSE(INDIRECT(ADDRESS(MATCH(A6,H:H,0),7)&"":""&ADDRESS(MATCH(A6,H:H,0)+B6-1,7)))),"""")"),"Andrew Chafin, Will Vest, Tarik Skubal, Shelby Miller, Jason Foley, Tyler Holton, Mason Englert, Brant Hurter, Joey Wentz, Ricky Vanasco, Alex Faedo, Brenan Hanifee, Kenta Maeda, Sean Guenther, Casey Mize, Reese Olson") -> Andrew Chafin, Will Vest, Tarik Skubal, Shelby Miller, Jason Foley, Tyler Holton, Mason Englert, Brant Hurter, Joey Wentz, Ricky Vanasco, Alex Faedo, Brenan Hanifee, Kenta Maeda, Sean Guenther, Casey Mize, Reese Olson | D6: =COUNTIFS(M:M,A6,P:P,">0",Q:Q,0) -> 1 | E6: =IFERROR(__xludf.DUMMYFUNCTION("IF(D6>0,JOIN("", "",TRANSPOSE(INDIRECT(ADDRESS(MATCH(A6,M:M,0),12)&"":""&ADDRESS(MATCH(A6,M:M,0)+D6-1,12)))),"""")"),"Sawyer Gipson-Long") -> Sawyer Gipson-Long | G6: Tanner Scott | H6: - - - | I6: 17586 | J6: {=INDEX('TJ List'!B:B,MATCH(I6,'TJ List'!N:N,0),0)} -> #N/A | L6: Lucas Giolito | M6: BOS | N6: Boston | O6: 15474 | P6: {=INDEX('TJ List'!B:B,MATCH(O6,'TJ List'!N:N,0),0)} -> 41152 | Q6: {=IFERROR(INDEX(I:I,MATCH(O6,I:I,0),0),0)} -> 0 | S6: Vidal Bruján | T6: MIA | U6: 20536 | W6: Martín Pérez | X6: - - - | Y6: 6902 | Z6: 41778
A7: CHW | B7: =COUNTIFS(H:H,A7,J:J,">0") -> 17 | C7: =IFERROR(__xludf.DUMMYFUNCTION("IF(B7>0,JOIN("", "",TRANSPOSE(INDIRECT(ADDRESS(MATCH(A7,H:H,0),7)&"":""&ADDRESS(MATCH(A7,H:H,0)+B7-1,7)))),"""")"),"Erick Fedde, Chris Flexen, Steven Wilson, Sean Burke, Michael Kopech, Chad Kuhl, Gus Varland, John Brebbia, Justin Anderson, Mike Clevinger, Jake Eder, Garrett Crochet, Matt Foster, Davis Martin, Jonathan Cannon, Michael Soroka, Jared Shuster") -> Erick Fedde, Chris Flexen, Steven Wilson, Sean Burke, Michael Kopech, Chad Kuhl, Gus Varland, John Brebbia, Justin Anderson, Mike Clevinger, Jake Eder, Garrett Crochet, Matt Foster, Davis Martin, Jonathan Cannon, Michael Soroka, Jared Shuster | D7: =COUNTIFS(M:M,A7,P:P,">0",Q:Q,0) -> 2 | E7: =IFERROR(__xludf.DUMMYFUNCTION("IF(D7>0,JOIN("", "",TRANSPOSE(INDIRECT(ADDRESS(MATCH(A7,M:M,0),12)&"":""&ADDRESS(MATCH(A7,M:M,0)+D7-1,12)))),"""")"),"Jimmy Lambert, Jesse Scholtens") -> Jimmy Lambert, Jesse Scholtens | G7: Frankie Montas | H7: - - - | I7: 14309 | J7: {=INDEX('TJ List'!B:B,MATCH(I7,'TJ List'!N:N,0),0)} -> 45909 | L7: Bryan Mata | M7: BOS | N7: Boston | O7: sa917784 | P7: {=INDEX('TJ List'!B:B,MATCH(O7,'TJ List'!N:N,0),0)} -> 44299 | Q7: {=IFERROR(INDEX(I:I,MATCH(O7,I:I,0),0),0)} -> 0 | S7: Oswaldo Cabrera | T7: NYY | U7: 21707 | W7: Erick Fedde | X7: - - - | Y7: 17425 | Z7: 41793
A8: PIT | B8: =COUNTIFS(H:H,A8,J:J,">0") -> 14 | C8: =IFERROR(__xludf.DUMMYFUNCTION("IF(B8>0,JOIN("", "",TRANSPOSE(INDIRECT(ADDRESS(MATCH(A8,H:H,0),7)&"":""&ADDRESS(MATCH(A8,H:H,0)+B8-1,7)))),"""")"),"Ryan Borucki, Justin Bruihl, Martín Pérez, Domingo Germán, Brady Feigl, Marco Gonzales, Brent Honeywell, Colin Holderman, Ben Heller, Jose E. Hernandez, Joey Wentz, Jalen Beeks, Daulton Jefferies, Mike Burrows") -> Ryan Borucki, Justin Bruihl, Martín Pérez, Domingo Germán, Brady Feigl, Marco Gonzales, Brent Honeywell, Colin Holderman, Ben Heller, Jose E. Hernandez, Joey Wentz, Jalen Beeks, Daulton Jefferies, Mike Burrows | D8: =COUNTIFS(M:M,A8,P:P,">0",Q:Q,0) -> 2 | E8: =IFERROR(__xludf.DUMMYFUNCTION("IF(D8>0,JOIN("", "",TRANSPOSE(INDIRECT(ADDRESS(MATCH(A8,M:M,0),12)&"":""&ADDRESS(MATCH(A8,M:M,0)+D8-1,12)))),"""")"),"Johan Oviedo, Dauri Moreta") -> Johan Oviedo, Dauri Moreta | G8: Jason Adam | H8: - - - | I8: 11861 | J8: {=INDEX('TJ List'!B:B,MATCH(I8,'TJ List'!N:N,0),0)} -> #N/A | L8: Liam Hendriks | M8: BOS | N8: Boston | O8: 3548 | P8: {=INDEX('TJ List'!B:B,MATCH(O8,'TJ List'!N:N,0),0)} -> 45140 | Q8: {=IFERROR(INDEX(I:I,MATCH(O8,I:I,0),0),0)} -> 0 | S8: Diego Castillo | T8: MIN | U8: 17496 | W8: Cole Sulser | X8: - - - | Y8: 15256 | Z8: 42005
A9: TEX | B9: =COUNTIFS(H:H,A9,J:J,">0") -> 14 | C9: =IFERROR(__xludf.DUMMYFUNCTION("IF(B9>0,JOIN("", "",TRANSPOSE(INDIRECT(ADDRESS(MATCH(A9,H:H,0),7)&"":""&ADDRESS(MATCH(A9,H:H,0)+B9-1,7)))),"""")"),"Andrew Chafin, Andrew Heaney, Nathan Eovaldi, Daniel Robert, Dane Dunning, Owen White, David Robertson, Matt Festa, Kirby Yates, José Leclerc, Jonathan Hernández, Tyler Mahle, Kumar Rocker, Jacob deGrom") -> Andrew Chafin, Andrew Heaney, Nathan Eovaldi, Daniel Robert, Dane Dunning, Owen White, David Robertson, Matt Festa, Kirby Yates, José Leclerc, Jonathan Hernández, Tyler Mahle, Kumar Rocker, Jacob deGrom | D9: =COUNTIFS(M:M,A9,P:P,">0",Q:Q,0) -> 1 | E9: =IFERROR(__xludf.DUMMYFUNCTION("IF(D9>0,JOIN("", "",TRANSPOSE(INDIRECT(ADDRESS(MATCH(A9,M:M,0),12)&"":""&ADDRESS(MATCH(A9,M:M,0)+D9-1,12)))),"""")"),"Carson Coleman") -> Carson Coleman | G9: Dennis Santana | H9: - - - | I9: 17878 | J9: {=INDEX('TJ List'!B:B,MATCH(I9,'TJ List'!N:N,0),0)} -> #N/A | L9: Chris Murphy | M9: BOS | N9: Boston | O9: 26214 | P9: {=INDEX('TJ List'!B:B,MATCH(O9,'TJ List'!N:N,0),0)} -> 45392 | Q9: {=IFERROR(INDEX(I:I,MATCH(O9,I:I,0),0),0)} -> 0 | S9: Willi Castro | T9: MIN | U9: 17338 | W9: Burch Smith | X9: - - - | Y9: 12784 | Z9: 42101
A10: ATL | B10: =COUNTIFS(H:H,A10,J:J,">0") -> 13 | C10: =IFERROR(__xludf.DUMMYFUNCTION("IF(B10>0,JOIN("", "",TRANSPOSE(INDIRECT(ADDRESS(MATCH(A10,H:H,0),7)&"":""&ADDRESS(MATCH(A10,H:H,0)+B10-1,7)))),"""")"),"Charlie Morton, Max Fried, A.J. Minter, Aaron Bummer, Spencer Strider, Chris Sale, John Brebbia, Spencer Schwellenbach, Daysbel Hernández, Luke Jackson, Tyler Matzek, Ray Kerr, Reynaldo López") -> Charlie Morton, Max Fried, A.J. Minter, Aaron Bummer, Spencer Strider, Chris Sale, John Brebbia, Spencer Schwellenbach, Daysbel Hernández, Luke Jackson, Tyler Matzek, Ray Kerr, Reynaldo López | D10: =COUNTIFS(M:M,A10,P:P,">0",Q:Q,0) -> 2 | E10: =IFERROR(__xludf.DUMMYFUNCTION("IF(D10>0,JOIN("", "",TRANSPOSE(INDIRECT(ADDRESS(MATCH(A10,M:M,0),12)&"":""&ADDRESS(MATCH(A10,M:M,0)+D10-1,12)))),"""")"),"Huascar Ynoa, Angel Perdomo") -> Huascar Ynoa, Angel Perdomo | G10: Carlos Estévez | H10: - - - | I10: 14542 | J10: {=INDEX('TJ List'!B:B,MATCH(I10,'TJ List'!N:N,0),0)} -> #N/A | L10: Jimmy Lambert | M10: CHW | N10: Chicago | O10: 19541 | P10: {=INDEX('TJ List'!B:B,MATCH(O10,'TJ List'!N:N,0),0)} -> 43641 | Q10: {=IFERROR(INDEX(I:I,MATCH(O10,I:I,0),0),0)} -> 0 | S10: Kody Clemens | T10: PHI | U10: 20572 | W10: Bryan Hoeing | X10: - - - | Y10: 26304 | Z10: 42156
A11: CIN | B11: =COUNTIFS(H:H,A11,J:J,">0") -> 12 | C11: =IFERROR(__xludf.DUMMYFUNCTION("IF(B11>0,JOIN("", "",TRANSPOSE(INDIRECT(ADDRESS(MATCH(A11,H:H,0),7)&"":""&ADDRESS(MATCH(A11,H:H,0)+B11-1,7)))),"""")"),"Casey Kelly, Alexis Díaz, Brandon Leibrandt, Brent Suter, Yosver Zulueta, Hunter Greene, Casey Legumina, Lyon Richardson, Tejay Antone, Justin Wilson, Brandon Williamson, Julian Aguiar") -> Casey Kelly, Alexis Díaz, Brandon Leibrandt, Brent Suter, Yosver Zulueta, Hunter Greene, Casey Legumina, Lyon Richardson, Tejay Antone, Justin Wilson, Brandon Williamson, Julian Aguiar | D11: =COUNTIFS(M:M,A11,P:P,">0",Q:Q,0) -> 0 | E11: =IFERROR(__xludf.DUMMYFUNCTION("IF(D11>0,JOIN("", "",TRANSPOSE(INDIRECT(ADDRESS(MATCH(A11,M:M,0),12)&"":""&ADDRESS(MATCH(A11,M:M,0)+D11-1,12)))),"""")"),"") | G11: Tanner Banks | H11: - - - | I11: 16990 | J11: {=INDEX('TJ List'!B:B,MATCH(I11,'TJ List'!N:N,0),0)} -> #N/A | L11: Jesse Scholtens | M11: CHW | N11: Chicago | O11: 19205 | P11: {=INDEX('TJ List'!B:B,MATCH(O11,'TJ List'!N:N,0),0)} -> 45352 | Q11: {=IFERROR(INDEX(I:I,MATCH(O11,I:I,0),0),0)} -> 0 | S11: Ernie Clement | T11: TOR | U11: 20352 | W11: Hunter Harvey | X11: - - - | Y11: 15507 | Z11: 42577
A12: LAA | B12: =COUNTIFS(H:H,A12,J:J,">0") -> 12 | C12: =IFERROR(__xludf.DUMMYFUNCTION("IF(B12>0,JOIN("", "",TRANSPOSE(INDIRECT(ADDRESS(MATCH(A12,H:H,0),7)&"":""&ADDRESS(MATCH(A12,H:H,0)+B12-1,7)))),"""")"),"Hunter Strickland, Matt Moore, José Cisnero, Ryan Miller, Zach Plesac, Johnny Cueto, Davis Daniel, Aaron Hicks, Ben Joyce, José Soriano, José Quijada, Zac Kristofak") -> Hunter Strickland, Matt Moore, José Cisnero, Ryan Miller, Zach Plesac, Johnny Cueto, Davis Daniel, Aaron Hicks, Ben Joyce, José Soriano, José Quijada, Zac Kristofak | D12: =COUNTIFS(M:M,A12,P:P,">0",Q:Q,0) -> 1 | E12: =IFERROR(__xludf.DUMMYFUNCTION("IF(D12>0,JOIN("", "",TRANSPOSE(INDIRECT(ADDRESS(MATCH(A12,M:M,0),12)&"":""&ADDRESS(MATCH(A12,M:M,0)+D12-1,12)))),"""")"),"Robert Stephenson") -> Robert Stephenson | G12: Aaron Civale | H12: - - - | I12: 19479 | J12: {=INDEX('TJ List'!B:B,MATCH(I12,'TJ List'!N:N,0),0)} -> #N/A | L12: Christian Roa | M12: CIN | N12: Cincinnati | O12: sa3014477 | P12: {=INDEX('TJ List'!B:B,MATCH(O12,'TJ List'!N:N,0),0)} -> #N/A | Q12: {=IFERROR(INDEX(I:I,MATCH(O12,I:I,0),0),0)} -> 0 | S12: Brandon Crawford | T12: STL | U12: 5343 | W12: Yimi García | X12: - - - | Y12: 12095 | Z12: 42668
A13: MIA | B13: =COUNTIFS(H:H,A13,J:J,">0") -> 13 | C13: =IFERROR(__xludf.DUMMYFUNCTION("IF(B13>0,JOIN("", "",TRANSPOSE(INDIRECT(ADDRESS(MATCH(A13,H:H,0),7)&"":""&ADDRESS(MATCH(A13,H:H,0)+B13-1,7)))),"""")"),"JT Chargois, Burch Smith, Bryan Hoeing, Kent Emanuel, Jesús Luzardo, Braxton Garrett, A.J. Puk, Yonny Chirinos, Lake Bachar, Vladimir Gutierrez, Max Meyer, Anthony Bender, Calvin Faucher") -> JT Chargois, Burch Smith, Bryan Hoeing, Kent Emanuel, Jesús Luzardo, Braxton Garrett, A.J. Puk, Yonny Chirinos, Lake Bachar, Vladimir Gutierrez, Max Meyer, Anthony Bender, Calvin Faucher | D13: =COUNTIFS(M:M,A13,P:P,">0",Q:Q,0) -> 2 | E13: =IFERROR(__xludf.DUMMYFUNCTION("IF(D13>0,JOIN("", "",TRANSPOSE(INDIRECT(ADDRESS(MATCH(A13,M:M,0),12)&"":""&ADDRESS(MATCH(A13,M:M,0)+D13-1,12)))),"""")"),"Sandy Alcantara, Eury Pérez") -> Sandy Alcantara, Eury Pérez | G13: Trevor Rogers | H13: - - - | I13: 22286 | J13: {=INDEX('TJ List'!B:B,MATCH(I13,'TJ List'!N:N,0),0)} -> #N/A | L13: Trevor Stephan | M13: CLE | N13: Cleveland | O13: 19932 | P13: {=INDEX('TJ List'!B:B,MATCH(O13,'TJ List'!N:N,0),0)} -> 45378 | Q13: {=IFERROR(INDEX(I:I,MATCH(O13,I:I,0),0),0)} -> 0 | S13: Kyle Farmer | T13: MIN | U13: 14813 | W13: Nick Robertson | X13: - - - | Y13: 26226 | Z13: 42736
A14: NYM | B14: =COUNTIFS(H:H,A14,J:J,">0") -> 15 | C14: =IFERROR(__xludf.DUMMYFUNCTION("IF(B14>0,JOIN("", "",TRANSPOSE(INDIRECT(ADDRESS(MATCH(A14,H:H,0),7)&"":""&ADDRESS(MATCH(A14,H:H,0)+B14-1,7)))),"""")"),"Cole Sulser, Adam Ottavino, Adrian Houser, Luis Severino, Matt Festa, Dedniel Núñez, Ty Adcock, Joey Lucchesi, Sean Reid-Foley, Brooks Raley, Drew Smith, Christian Scott, Sean Manaea, David Peterson, Tylor Megill") -> Cole Sulser, Adam Ottavino, Adrian Houser, Luis Severino, Matt Festa, Dedniel Núñez, Ty Adcock, Joey Lucchesi, Sean Reid-Foley, Brooks Raley, Drew Smith, Christian Scott, Sean Manaea, David Peterson, Tylor Megill | D14: =COUNTIFS(M:M,A14,P:P,">0",Q:Q,0) -> 0 | E14: =IFERROR(__xludf.DUMMYFUNCTION("IF(D14>0,JOIN("", "",TRANSPOSE(INDIRECT(ADDRESS(MATCH(A14,M:M,0),12)&"":""&ADDRESS(MATCH(A14,M:M,0)+D14-1,12)))),"""")"),"") | G14: Jakob Junis | H14: - - - | I14: 13619 | J14: {=INDEX('TJ List'!B:B,MATCH(I14,'TJ List'!N:N,0),0)} -> #N/A | L14: James Karinchak | M14: CLE | N14: Cleveland | O14: 20151 | P14: {=INDEX('TJ List'!B:B,MATCH(O14,'TJ List'!N:N,0),0)} -> #N/A | Q14: {=IFERROR(INDEX(I:I,MATCH(O14,I:I,0),0),0)} -> 0 | S14: Tyler Fitzgerald | T14: SFG | U14: 26208 | W14: Brent Honeywell | X14: - - - | Y14: 16466 | Z14: 43158
A15: BAL | B15: =COUNTIFS(H:H,A15,J:J,">0") -> 12 | C15: =IFERROR(__xludf.DUMMYFUNCTION("IF(B15>0,JOIN("", "",TRANSPOSE(INDIRECT(ADDRESS(MATCH(A15,H:H,0),7)&"":""&ADDRESS(MATCH(A15,H:H,0)+B15-1,7)))),"""")"),"Albert Suárez, Danny Coulombe, Cole Irvin, Matt Krook, Jacob Webb, Burch Smith, Tyler Wells, Seranthony Domínguez, Matt Bowman, John Means, Kyle Bradish, Corbin Burnes") -> Albert Suárez, Danny Coulombe, Cole Irvin, Matt Krook, Jacob Webb, Burch Smith, Tyler Wells, Seranthony Domínguez, Matt Bowman, John Means, Kyle Bradish, Corbin Burnes | D15: =COUNTIFS(M:M,A15,P:P,">0",Q:Q,0) -> 1 | E15: =IFERROR(__xludf.DUMMYFUNCTION("IF(D15>0,JOIN("", "",TRANSPOSE(INDIRECT(ADDRESS(MATCH(A15,M:M,0),12)&"":""&ADDRESS(MATCH(A15,M:M,0)+D15-1,12)))),"""")"),"Félix Bautista") -> Félix Bautista | G15: Nick Mears | H15: - - - | I15: 25376 | J15: {=INDEX('TJ List'!B:B,MATCH(I15,'TJ List'!N:N,0),0)} -> #N/A | L15: Daniel Bard | M15: COL | N15: Colorado | O15: 7115 | P15: {=INDEX('TJ List'!B:B,MATCH(O15,'TJ List'!N:N,0),0)} -> #N/A | Q15: {=IFERROR(INDEX(I:I,MATCH(O15,I:I,0),0),0)} -> 0 | S15: Luis Guillorme | T15: - - - | U15: 16451 | W15: A.J. Puk | X15: - - - | Y15: 19343 | Z15: 43200
A16: CHC | B16: =COUNTIFS(H:H,A16,J:J,">0") -> 12 | C16: =IFERROR(__xludf.DUMMYFUNCTION("IF(B16>0,JOIN("", "",TRANSPOSE(INDIRECT(ADDRESS(MATCH(A16,H:H,0),7)&"":""&ADDRESS(MATCH(A16,H:H,0)+B16-1,7)))),"""")"),"Keegan Thompson, Drew Smyly, Justin Steele, Julian Merryweather, Mark Leiter Jr., Ben Brown, Jameson Taillon, Trey Wingenter, Richard Lovelady, Ethan Roberts, Adbert Alzolay, Shota Imanaga") -> Keegan Thompson, Drew Smyly, Justin Steele, Julian Merryweather, Mark Leiter Jr., Ben Brown, Jameson Taillon, Trey Wingenter, Richard Lovelady, Ethan Roberts, Adbert Alzolay, Shota Imanaga | D16: =COUNTIFS(M:M,A16,P:P,">0",Q:Q,0) -> 0 | E16: =IFERROR(__xludf.DUMMYFUNCTION("IF(D16>0,JOIN("", "",TRANSPOSE(INDIRECT(ADDRESS(MATCH(A16,M:M,0),12)&"":""&ADDRESS(MATCH(A16,M:M,0)+D16-1,12)))),"""")"),"") | G16: Michael Lorenzen | H16: - - - | I16: 14843 | J16: {=INDEX('TJ List'!B:B,MATCH(I16,'TJ List'!N:N,0),0)} -> #N/A | L16: Sawyer Gipson-Long | M16: DET | N16: Detroit | O16: 26048 | P16: {=INDEX('TJ List'!B:B,MATCH(O16,'TJ List'!N:N,0),0)} -> 45404 | Q16: {=IFERROR(INDEX(I:I,MATCH(O16,I:I,0),0),0)} -> 0 | S16: Garrett Hampson | T16: KCR | U16: 19262 | W16: Michael Kopech | X16: - - - | Y16: 17282 | Z16: 43361
A17: CLE | B17: =COUNTIFS(H:H,A17,J:J,">0") -> 12 | C17: =IFERROR(__xludf.DUMMYFUNCTION("IF(B17>0,JOIN("", "",TRANSPOSE(INDIRECT(ADDRESS(MATCH(A17,H:H,0),7)&"":""&ADDRESS(MATCH(A17,H:H,0)+B17-1,7)))),"""")"),"Carlos Carrasco, Scott Barlow, Alex Cobb, Peter Strzelecki, Sam Hentges, Pedro Avila, Tyler Beede, Erik Sabrowski, Anthony Gose, Matthew Boyd, Shane Bieber, Tanner Bibee") -> Carlos Carrasco, Scott Barlow, Alex Cobb, Peter Strzelecki, Sam Hentges, Pedro Avila, Tyler Beede, Erik Sabrowski, Anthony Gose, Matthew Boyd, Shane Bieber, Tanner Bibee | D17: =COUNTIFS(M:M,A17,P:P,">0",Q:Q,0) -> 1 | E17: =IFERROR(__xludf.DUMMYFUNCTION("IF(D17>0,JOIN("", "",TRANSPOSE(INDIRECT(ADDRESS(MATCH(A17,M:M,0),12)&"":""&ADDRESS(MATCH(A17,M:M,0)+D17-1,12)))),"""")"),"Trevor Stephan") -> Trevor Stephan | G17: Jesus Tinoco | H17: - - - | I17: 16300 | J17: {=INDEX('TJ List'!B:B,MATCH(I17,'TJ List'!N:N,0),0)} -> #N/A | L17: Brendan White | M17: DET | N17: Detroit | O17: 26024 | P17: {=INDEX('TJ List'!B:B,MATCH(O17,'TJ List'!N:N,0),0)} -> #N/A | Q17: {=IFERROR(INDEX(I:I,MATCH(O17,I:I,0),0),0)} -> 0 | S17: Austin Hedges | T17: CLE | U17: 12976 | W17: Mark Leiter Jr. | X17: - - - | Y17: 15551 | Z17: 43536
A18: PHI | B18: =COUNTIFS(H:H,A18,J:J,">0") -> 11 | C18: =IFERROR(__xludf.DUMMYFUNCTION("IF(B18>0,JOIN("", "",TRANSPOSE(INDIRECT(ADDRESS(MATCH(A18,H:H,0),7)&"":""&ADDRESS(MATCH(A18,H:H,0)+B18-1,7)))),"""")"),"Matt Strahm, Jeff Hoffman, Zack Wheeler, Taijuan Walker, Michael Mercado, Seranthony Domínguez, Max Lazar, Spencer Turnbull, Tyler Phillips, Seth Johnson, Luis F. Ortiz") -> Matt Strahm, Jeff Hoffman, Zack Wheeler, Taijuan Walker, Michael Mercado, Seranthony Domínguez, Max Lazar, Spencer Turnbull, Tyler Phillips, Seth Johnson, Luis F. Ortiz | D18: =COUNTIFS(M:M,A18,P:P,">0",Q:Q,0) -> 0 | E18: =IFERROR(__xludf.DUMMYFUNCTION("IF(D18>0,JOIN("", "",TRANSPOSE(INDIRECT(ADDRESS(MATCH(A18,M:M,0),12)&"":""&ADDRESS(MATCH(A18,M:M,0)+D18-1,12)))),"""")"),"") | G18: Shawn Armstrong | H18: - - - | I18: 12857 | J18: {=INDEX('TJ List'!B:B,MATCH(I18,'TJ List'!N:N,0),0)} -> #N/A | L18: Kendall Graveman | M18: HOU | N18: Houston | O18: 15514 | P18: {=INDEX('TJ List'!B:B,MATCH(O18,'TJ List'!N:N,0),0)} -> 43311 | Q18: {=IFERROR(INDEX(I:I,MATCH(O18,I:I,0),0),0)} -> 0 | S18: Tyler Heineman | T18: TOR | U18: 13897 | W18: Gus Varland | X18: - - - | Y18: 24737 | Z18: 43678
A19: SDP | B19: =COUNTIFS(H:H,A19,J:J,">0") -> 11 | C19: =IFERROR(__xludf.DUMMYFUNCTION("IF(B19>0,JOIN("", "",TRANSPOSE(INDIRECT(ADDRESS(MATCH(A19,H:H,0),7)&"":""&ADDRESS(MATCH(A19,H:H,0)+B19-1,7)))),"""")"),"Martín Pérez, Dylan Cease, Yu Darvish, Bryan Hoeing, Jhony Brito, Robert Suarez, Jeremiah Estrada, Tom Cosgrove, Pedro Avila, Adrian Morejon, Joe Musgrove") -> Martín Pérez, Dylan Cease, Yu Darvish, Bryan Hoeing, Jhony Brito, Robert Suarez, Jeremiah Estrada, Tom Cosgrove, Pedro Avila, Adrian Morejon, Joe Musgrove | D19: =COUNTIFS(M:M,A19,P:P,">0",Q:Q,0) -> 1 | E19: =IFERROR(__xludf.DUMMYFUNCTION("IF(D19>0,JOIN("", "",TRANSPOSE(INDIRECT(ADDRESS(MATCH(A19,M:M,0),12)&"":""&ADDRESS(MATCH(A19,M:M,0)+D19-1,12)))),"""")"),"Luis Patiño") -> Luis Patiño | G19: Huascar Brazobán | H19: - - - | I19: 6107 | J19: {=INDEX('TJ List'!B:B,MATCH(I19,'TJ List'!N:N,0),0)} -> #N/A | L19: Lance McCullers Jr. | M19: HOU | N19: Houston | O19: 14120 | P19: {=INDEX('TJ List'!B:B,MATCH(O19,'TJ List'!N:N,0),0)} -> 43410 | Q19: {=IFERROR(INDEX(I:I,MATCH(O19,I:I,0),0),0)} -> 0 | S19: David Hensley | T19: MIA | U19: 25111 | W19: Pedro Avila | X19: - - - | Y19: 18864 | Z19: 43709
A20: TOR | B20: =COUNTIFS(H:H,A20,J:J,">0") -> 11 | C20: =IFERROR(__xludf.DUMMYFUNCTION("IF(B20>0,JOIN("", "",TRANSPOSE(INDIRECT(ADDRESS(MATCH(A20,H:H,0),7)&"":""&ADDRESS(MATCH(A20,H:H,0)+B20-1,7)))),"""")"),"Tommy Nance, Mitch White, Jordan Romano, Chris Bassitt, Yimi García, Nick Robertson, Zach Pop, Ryan Burr, Tim Mayza, Chad Green, Alek Manoah") -> Tommy Nance, Mitch White, Jordan Romano, Chris Bassitt, Yimi García, Nick Robertson, Zach Pop, Ryan Burr, Tim Mayza, Chad Green, Alek Manoah | D20: =COUNTIFS(M:M,A20,P:P,">0",Q:Q,0) -> 0 | E20: =IFERROR(__xludf.DUMMYFUNCTION("IF(D20>0,JOIN("", "",TRANSPOSE(INDIRECT(ADDRESS(MATCH(A20,M:M,0),12)&"":""&ADDRESS(MATCH(A20,M:M,0)+D20-1,12)))),"""")"),"") | G20: Michael Tonkin | H20: - - - | I20: 10315 | J20: {=INDEX('TJ List'!B:B,MATCH(I20,'TJ List'!N:N,0),0)} -> #N/A | L20: Luis Garcia | M20: HOU | N20: Houston | O20: 23735 | P20: {=INDEX('TJ List'!B:B,MATCH(O20,'TJ List'!N:N,0),0)} -> 45931 | Q20: {=IFERROR(INDEX(I:I,MATCH(O20,I:I,0),0),0)} -> 0 | S20: Enrique Hernández | T20: LAD | U20: 10472 | W20: Tim Mayza | X20: - - - | Y20: 15042 | Z20: 43726
A21: HOU | B21: =COUNTIFS(H:H,A21,J:J,">0") -> 11 | C21: =IFERROR(__xludf.DUMMYFUNCTION("IF(B21>0,JOIN("", "",TRANSPOSE(INDIRECT(ADDRESS(MATCH(A21,H:H,0),7)&"":""&ADDRESS(MATCH(A21,H:H,0)+B21-1,7)))),"""")"),"J.P. France, Nick Hernandez, Rafael Montero, Alex Speas, Caleb Ferguson, Justin Verlander, Blair Henley, Forrest Whitley, Bryan King, Cristian Javier, Framber Valdez") -> J.P. France, Nick Hernandez, Rafael Montero, Alex Speas, Caleb Ferguson, Justin Verlander, Blair Henley, Forrest Whitley, Bryan King, Cristian Javier, Framber Valdez | D21: =COUNTIFS(M:M,A21,P:P,">0",Q:Q,0) -> 5 | E21: =IFERROR(__xludf.DUMMYFUNCTION("IF(D21>0,JOIN("", "",TRANSPOSE(INDIRECT(ADDRESS(MATCH(A21,M:M,0),12)&"":""&ADDRESS(MATCH(A21,M:M,0)+D21-1,12)))),"""")"),"Kendall Graveman, Lance McCullers Jr., Luis Garcia, Penn Murfee, José Urquidy") -> Kendall Graveman, Lance McCullers Jr., Luis Garcia, Penn Murfee, José Urquidy | G21: Dylan Floro | H21: - - - | I21: 13394 | J21: {=INDEX('TJ List'!B:B,MATCH(I21,'TJ List'!N:N,0),0)} -> #N/A | L21: Penn Murfee | M21: HOU | N21: Houston | O21: 25174 | P21: {=INDEX('TJ List'!B:B,MATCH(O21,'TJ List'!N:N,0),0)} -> 45108 | Q21: {=IFERROR(INDEX(I:I,MATCH(O21,I:I,0),0),0)} -> 0 | S21: Aaron Hicks | T21: LAA | U21: 5297 | W21: Matt Festa | X21: - - - | Y21: 19330 | Z21: 43895
A22: ARI | B22: =COUNTIFS(H:H,A22,J:J,">0") -> 11 | C22: =IFERROR(__xludf.DUMMYFUNCTION("IF(B22>0,JOIN("", "",TRANSPOSE(INDIRECT(ADDRESS(MATCH(A22,H:H,0),7)&"":""&ADDRESS(MATCH(A22,H:H,0)+B22-1,7)))),"""")"),"Scott McGough, Ryan Thompson, Joe Mantiply, A.J. Puk, Jordan Montgomery, Matt Bowman, Andrew Saalfrank, Justin Martinez, Humberto Castellanos, Brandon Pfaadt, Zac Gallen") -> Scott McGough, Ryan Thompson, Joe Mantiply, A.J. Puk, Jordan Montgomery, Matt Bowman, Andrew Saalfrank, Justin Martinez, Humberto Castellanos, Brandon Pfaadt, Zac Gallen | D22: =COUNTIFS(M:M,A22,P:P,">0",Q:Q,0) -> 1 | E22: =IFERROR(__xludf.DUMMYFUNCTION("IF(D22>0,JOIN("", "",TRANSPOSE(INDIRECT(ADDRESS(MATCH(A22,M:M,0),12)&"":""&ADDRESS(MATCH(A22,M:M,0)+D22-1,12)))),"""")"),"Drey Jameson") -> Drey Jameson | G22: Tyson Miller | H22: - - - | I22: 19976 | J22: {=INDEX('TJ List'!B:B,MATCH(I22,'TJ List'!N:N,0),0)} -> #N/A | L22: José Urquidy | M22: HOU | N22: Houston | O22: 18413 | P22: {=INDEX('TJ List'!B:B,MATCH(O22,'TJ List'!N:N,0),0)} -> 45448 | Q22: {=IFERROR(INDEX(I:I,MATCH(O22,I:I,0),0),0)} -> 0 | S22: Grae Kessinger | T22: HOU | U22: 25813 | W22: Joey Wentz | X22: - - - | Y22: 19962 | Z22: 43907
A23: BOS | B23: =COUNTIFS(H:H,A23,J:J,">0") -> 10 | C23: =IFERROR(__xludf.DUMMYFUNCTION("IF(B23>0,JOIN("", "",TRANSPOSE(INDIRECT(ADDRESS(MATCH(A23,H:H,0),7)&"":""&ADDRESS(MATCH(A23,H:H,0)+B23-1,7)))),"""")"),"Cam Booser, Rich Hill, Bailey Horn, Zach Penrod, Garrett Whitlock, Kutter Crawford, Zack Kelly, Trey Wingenter, James Paxton, Tanner Houck") -> Cam Booser, Rich Hill, Bailey Horn, Zach Penrod, Garrett Whitlock, Kutter Crawford, Zack Kelly, Trey Wingenter, James Paxton, Tanner Houck | D23: =COUNTIFS(M:M,A23,P:P,">0",Q:Q,0) -> 4 | E23: =IFERROR(__xludf.DUMMYFUNCTION("IF(D23>0,JOIN("", "",TRANSPOSE(INDIRECT(ADDRESS(MATCH(A23,M:M,0),12)&"":""&ADDRESS(MATCH(A23,M:M,0)+D23-1,12)))),"""")"),"Lucas Giolito, Bryan Mata, Liam Hendriks, Chris Murphy") -> Lucas Giolito, Bryan Mata, Liam Hendriks, Chris Murphy | G23: Tim Hill | H23: - - - | I23: 16814 | J23: {=INDEX('TJ List'!B:B,MATCH(I23,'TJ List'!N:N,0),0)} -> #N/A | L23: Bennett Sousa | M23: HOU | N23: Houston | O23: 21345 | P23: {=INDEX('TJ List'!B:B,MATCH(O23,'TJ List'!N:N,0),0)} -> #N/A | Q23: {=IFERROR(INDEX(I:I,MATCH(O23,I:I,0),0),0)} -> 0 | S23: Isiah Kiner-Falefa | T23: TOR | U23: 16512 | W23: John Brebbia | X23: - - - | Y23: 12777 | Z23: 43990
A24: MIL | B24: =COUNTIFS(H:H,A24,J:J,">0") -> 9 | C24: =IFERROR(__xludf.DUMMYFUNCTION("IF(B24>0,JOIN("", "",TRANSPOSE(INDIRECT(ADDRESS(MATCH(A24,H:H,0),7)&"":""&ADDRESS(MATCH(A24,H:H,0)+B24-1,7)))),"""")"),"Trevor Megill, Mitch White, Colin Rea, Devin Williams, Kevin Herget, Bradley Blalock, Joe Ross, Wade Miley, Robert Gasser") -> Trevor Megill, Mitch White, Colin Rea, Devin Williams, Kevin Herget, Bradley Blalock, Joe Ross, Wade Miley, Robert Gasser | D24: =COUNTIFS(M:M,A24,P:P,">0",Q:Q,0) -> 0 | E24: =IFERROR(__xludf.DUMMYFUNCTION("IF(D24>0,JOIN("", "",TRANSPOSE(INDIRECT(ADDRESS(MATCH(A24,M:M,0),12)&"":""&ADDRESS(MATCH(A24,M:M,0)+D24-1,12)))),"""")"),"") | G24: Gregory Soto | H24: - - - | I24: 19677 | J24: {=INDEX('TJ List'!B:B,MATCH(I24,'TJ List'!N:N,0),0)} -> #N/A | L24: Oliver Ortega | M24: HOU | N24: Houston | O24: 21025 | P24: {=INDEX('TJ List'!B:B,MATCH(O24,'TJ List'!N:N,0),0)} -> #N/A | Q24: {=IFERROR(INDEX(I:I,MATCH(O24,I:I,0),0),0)} -> 0 | S24: Andrew Knizner | T24: TEX | U24: 19514 | W24: Trey Wingenter | X24: - - - | Y24: 17793 | Z24: 44029
A25: SFG | B25: =COUNTIFS(H:H,A25,J:J,">0") -> 10 | C25: =IFERROR(__xludf.DUMMYFUNCTION("IF(B25>0,JOIN("", "",TRANSPOSE(INDIRECT(ADDRESS(MATCH(A25,H:H,0),7)&"":""&ADDRESS(MATCH(A25,H:H,0)+B25-1,7)))),"""")"),"Mitch White, Logan Webb, Raymond Burgos, Jordan Hicks, Keaton Winn, Luke Jackson, Daulton Jefferies, Robbie Ray, Austin Warren, Blake Snell") -> Mitch White, Logan Webb, Raymond Burgos, Jordan Hicks, Keaton Winn, Luke Jackson, Daulton Jefferies, Robbie Ray, Austin Warren, Blake Snell | D25: =COUNTIFS(M:M,A25,P:P,">0",Q:Q,0) -> 0 | E25: =IFERROR(__xludf.DUMMYFUNCTION("IF(D25>0,JOIN("", "",TRANSPOSE(INDIRECT(ADDRESS(MATCH(A25,M:M,0),12)&"":""&ADDRESS(MATCH(A25,M:M,0)+D25-1,12)))),"""")"),"") | G25: Paul Blackburn | H25: - - - | I25: 14739 | J25: {=INDEX('TJ List'!B:B,MATCH(I25,'TJ List'!N:N,0),0)} -> #N/A | L25: Josh Taylor | M25: KCR | N25: Kansas City | O25: 17359 | P25: {=INDEX('TJ List'!B:B,MATCH(O25,'TJ List'!N:N,0),0)} -> #N/A | Q25: {=IFERROR(INDEX(I:I,MATCH(O25,I:I,0),0),0)} -> 0 | S25: Nick Loftin | T25: KCR | U25: 27630 | W25: Seranthony Domínguez | X25: - - - | Y25: 19249 | Z25: 44042
A26: STL | B26: =COUNTIFS(H:H,A26,J:J,">0") -> 9 | C26: =IFERROR(__xludf.DUMMYFUNCTION("IF(B26>0,JOIN("", "",TRANSPOSE(INDIRECT(ADDRESS(MATCH(A26,H:H,0),7)&"":""&ADDRESS(MATCH(A26,H:H,0)+B26-1,7)))),"""")"),"Steven Matz, Giovanny Gallegos, Kyle Gibson, Erick Fedde, Lance Lynn, John King, Nick Robertson, JoJo Romero, Andrew Kittredge") -> Steven Matz, Giovanny Gallegos, Kyle Gibson, Erick Fedde, Lance Lynn, John King, Nick Robertson, JoJo Romero, Andrew Kittredge | D26: =COUNTIFS(M:M,A26,P:P,">0",Q:Q,0) -> 1 | E26: =IFERROR(__xludf.DUMMYFUNCTION("IF(D26>0,JOIN("", "",TRANSPOSE(INDIRECT(ADDRESS(MATCH(A26,M:M,0),12)&"":""&ADDRESS(MATCH(A26,M:M,0)+D26-1,12)))),"""")"),"Keynan Middleton") -> Keynan Middleton | G26: Brock Burke | H26: - - - | I26: 17968 | J26: {=INDEX('TJ List'!B:B,MATCH(I26,'TJ List'!N:N,0),0)} -> #N/A | L26: Kyle Wright | M26: KCR | N26: Kansas City | O26: 19665 | P26: {=INDEX('TJ List'!B:B,MATCH(O26,'TJ List'!N:N,0),0)} -> #N/A | Q26: {=IFERROR(INDEX(I:I,MATCH(O26,I:I,0),0),0)} -> 0 | S26: Luke Maile | T26: CIN | U26: 13355 | W26: Matt Bowman | X26: - - - | Y26: 13528 | Z26: 44075
A27: TBR | B27: =COUNTIFS(H:H,A27,J:J,">0") -> 9 | C27: =IFERROR(__xludf.DUMMYFUNCTION("IF(B27>0,JOIN("", "",TRANSPOSE(INDIRECT(ADDRESS(MATCH(A27,H:H,0),7)&"":""&ADDRESS(MATCH(A27,H:H,0)+B27-1,7)))),"""")"),"Cole Sulser, Pete Fairbanks, Drew Rasmussen, Colin Poche, Jacob Lopez, Chris Devenski, Richard Lovelady, Shane Baz, Jeffrey Springs") -> Cole Sulser, Pete Fairbanks, Drew Rasmussen, Colin Poche, Jacob Lopez, Chris Devenski, Richard Lovelady, Shane Baz, Jeffrey Springs | D27: =COUNTIFS(M:M,A27,P:P,">0",Q:Q,0) -> 1 | E27: =IFERROR(__xludf.DUMMYFUNCTION("IF(D27>0,JOIN("", "",TRANSPOSE(INDIRECT(ADDRESS(MATCH(A27,M:M,0),12)&"":""&ADDRESS(MATCH(A27,M:M,0)+D27-1,12)))),"""")"),"Shane McClanahan") -> Shane McClanahan | G27: Luis García | H27: - - - | I27: 6984 | J27: {=INDEX('TJ List'!B:B,MATCH(I27,'TJ List'!N:N,0),0)} -> #N/A | L27: Robert Stephenson | M27: LAA | N27: Los Angeles | O27: 13594 | P27: {=INDEX('TJ List'!B:B,MATCH(O27,'TJ List'!N:N,0),0)} -> 45412 | Q27: {=IFERROR(INDEX(I:I,MATCH(O27,I:I,0),0),0)} -> 0 | S27: James McCann | T27: BAL | U27: 12859 | W27: Jalen Beeks | X27: - - - | Y27: 17192 | Z27: 44076
A28: MIN | B28: =COUNTIFS(H:H,A28,J:J,">0") -> 10 | C28: =IFERROR(__xludf.DUMMYFUNCTION("IF(B28>0,JOIN("", "",TRANSPOSE(INDIRECT(ADDRESS(MATCH(A28,H:H,0),7)&"":""&ADDRESS(MATCH(A28,H:H,0)+B28-1,7)))),"""")"),"Pablo López, Cole Irvin, Bailey Ober, Justin Topa, Matt Bowman, Brock Stewart, Chris Paddack, Daniel Duarte, Joe Ryan, Griffin Jax") -> Pablo López, Cole Irvin, Bailey Ober, Justin Topa, Matt Bowman, Brock Stewart, Chris Paddack, Daniel Duarte, Joe Ryan, Griffin Jax | D28: =COUNTIFS(M:M,A28,P:P,">0",Q:Q,0) -> 0 | E28: =IFERROR(__xludf.DUMMYFUNCTION("IF(D28>0,JOIN("", "",TRANSPOSE(INDIRECT(ADDRESS(MATCH(A28,M:M,0),12)&"":""&ADDRESS(MATCH(A28,M:M,0)+D28-1,12)))),"""")"),"") | G28: Hunter Bigge | H28: - - - | I28: 26259 | J28: {=INDEX('TJ List'!B:B,MATCH(I28,'TJ List'!N:N,0),0)} -> #N/A | L28: Kelvin Caceres | M28: LAA | N28: Los Angeles | O28: 24681 | P28: {=INDEX('TJ List'!B:B,MATCH(O28,'TJ List'!N:N,0),0)} -> #N/A | Q28: {=IFERROR(INDEX(I:I,MATCH(O28,I:I,0),0),0)} -> 0 | S28: Zach McKinstry | T28: DET | U28: 19392 | W28: Ricky Vanasco | X28: - - - | Y28: 23391 | Z28: 44095
A29: KCR | B29: =COUNTIFS(H:H,A29,J:J,">0") -> 7 | C29: =IFERROR(__xludf.DUMMYFUNCTION("IF(B29>0,JOIN("", "",TRANSPOSE(INDIRECT(ADDRESS(MATCH(A29,H:H,0),7)&"":""&ADDRESS(MATCH(A29,H:H,0)+B29-1,7)))),"""")"),"Hunter Harvey, Will Smith, Matt Sauer, Cole Ragans, Jonathan Bowlan, Dan Altavilla, Kris Bubic") -> Hunter Harvey, Will Smith, Matt Sauer, Cole Ragans, Jonathan Bowlan, Dan Altavilla, Kris Bubic | D29: =COUNTIFS(M:M,A29,P:P,">0",Q:Q,0) -> 0 | E29: =IFERROR(__xludf.DUMMYFUNCTION("IF(D29>0,JOIN("", "",TRANSPOSE(INDIRECT(ADDRESS(MATCH(A29,M:M,0),12)&"":""&ADDRESS(MATCH(A29,M:M,0)+D29-1,12)))),"""")"),"") | G29: Enoli Paredes | H29: - - - | I29: 20447 | J29: {=INDEX('TJ List'!B:B,MATCH(I29,'TJ List'!N:N,0),0)} -> #N/A | L29: Dustin May | M29: LAD | N29: Los Angeles | O29: 19716 | P29: {=INDEX('TJ List'!B:B,MATCH(O29,'TJ List'!N:N,0),0)} -> 45125 | Q29: {=IFERROR(INDEX(I:I,MATCH(O29,I:I,0),0),0)} -> 0 | S29: Danny Mendick | T29: CHW | U29: 18889 | W29: Caleb Ferguson | X29: - - - | Y29: 19349 | Z29: 44096
A30: OAK | B30: =COUNTIFS(H:H,A30,J:J,">0") -> 7 | C30: =IFERROR(__xludf.DUMMYFUNCTION("IF(B30>0,JOIN("", "",TRANSPOSE(INDIRECT(ADDRESS(MATCH(A30,H:H,0),7)&"":""&ADDRESS(MATCH(A30,H:H,0)+B30-1,7)))),"""")"),"Alex Wood, Ross Stripling, Hogan Harris, J.T. Ginn, Gerardo Reyes, Brady Basso, Luis Medina") -> Alex Wood, Ross Stripling, Hogan Harris, J.T. Ginn, Gerardo Reyes, Brady Basso, Luis Medina | D30: =COUNTIFS(M:M,A30,P:P,">0",Q:Q,0) -> 2 | E30: =IFERROR(__xludf.DUMMYFUNCTION("IF(D30>0,JOIN("", "",TRANSPOSE(INDIRECT(ADDRESS(MATCH(A30,M:M,0),12)&"":""&ADDRESS(MATCH(A30,M:M,0)+D30-1,12)))),"""")"),"Trevor Gott, Ken Waldichuk") -> Trevor Gott, Ken Waldichuk | G30: Dillon Tate | H30: - - - | I30: 17796 | J30: {=INDEX('TJ List'!B:B,MATCH(I30,'TJ List'!N:N,0),0)} -> #N/A | L30: Tony Gonsolin | M30: LAD | N30: Los Angeles | O30: 19388 | P30: {=INDEX('TJ List'!B:B,MATCH(O30,'TJ List'!N:N,0),0)} -> 45170 | Q30: {=IFERROR(INDEX(I:I,MATCH(O30,I:I,0),0),0)} -> 0 | S30: Matt Mervis | T30: CHC | U30: 27845 | W30: Jonathan Hernández | X30: - - - | Y30: 17464 | Z30: 44298
